<?xml version='1.0'?>

<robot name="rear_wheel" xmlns:xacro="http://www.ros.org/wiki/xacro">
  <link name='rear_wheel'>
    <collision name='rear_wheel_collision'>
      <geometry>
        <cylinder length='0.01' radius='0.04'/>
      </geometry>
    </collision>

    <inertial>
      <mass value="2"/>
      <inertia
        ixx="0.1" ixy="0" ixz="0"
        iyy="0.1" iyz="0"
        izz="0.1"
      />
    </inertial>

    <visual name='rear_wheel_visual'>
      <geometry>
        <cylinder length='0.01' radius='0.04'/>
      </geometry>
    </visual>
  </link>

  <joint type="continuous" name="rear_wheel_joint">
    <origin xyz="0 0 -0.06" rpy="-1.5708 0 0"/>
    <child link="rear_wheel"/>
    <parent link="rear_caster"/>
    <axis xyz="0 0 1" rpy="0 0 0"/>
  </joint>
</robot>